2024-07-08 13:22:49,509 INFO    StreamThr :28940 [internal.py:wandb_internal():85] W&B internal server running at pid: 28940, started at: 2024-07-08 13:22:49.508553
2024-07-08 13:22:49,510 DEBUG   HandlerThread:28940 [handler.py:handle_request():158] handle_request: status
2024-07-08 13:22:49,512 INFO    WriterThread:28940 [datastore.py:open_for_write():87] open: D:\Works\SomeCodes\testing-wandb\wandb\run-20240708_132249-glh15ugv\run-glh15ugv.wandb
2024-07-08 13:22:49,513 DEBUG   SenderThread:28940 [sender.py:send():379] send: header
2024-07-08 13:22:49,514 DEBUG   SenderThread:28940 [sender.py:send():379] send: run
2024-07-08 13:22:52,853 INFO    SenderThread:28940 [retry.py:__call__():172] Retry attempt failed:
Traceback (most recent call last):
  File "C:\ProgramData\miniconda3\envs\wandbtestp11\Lib\site-packages\urllib3\connectionpool.py", line 466, in _make_request
    self._validate_conn(conn)
  File "C:\ProgramData\miniconda3\envs\wandbtestp11\Lib\site-packages\urllib3\connectionpool.py", line 1095, in _validate_conn
    conn.connect()
  File "C:\ProgramData\miniconda3\envs\wandbtestp11\Lib\site-packages\urllib3\connection.py", line 652, in connect
    sock_and_verified = _ssl_wrap_socket_and_match_hostname(
                        ^^^^^^^^^^^^^^^^^^^^^^^^^^^^^^^^^^^^
  File "C:\ProgramData\miniconda3\envs\wandbtestp11\Lib\site-packages\urllib3\connection.py", line 805, in _ssl_wrap_socket_and_match_hostname
    ssl_sock = ssl_wrap_socket(
               ^^^^^^^^^^^^^^^^
  File "C:\ProgramData\miniconda3\envs\wandbtestp11\Lib\site-packages\urllib3\util\ssl_.py", line 465, in ssl_wrap_socket
    ssl_sock = _ssl_wrap_socket_impl(sock, context, tls_in_tls, server_hostname)
               ^^^^^^^^^^^^^^^^^^^^^^^^^^^^^^^^^^^^^^^^^^^^^^^^^^^^^^^^^^^^^^^^^
  File "C:\ProgramData\miniconda3\envs\wandbtestp11\Lib\site-packages\urllib3\util\ssl_.py", line 509, in _ssl_wrap_socket_impl
    return ssl_context.wrap_socket(sock, server_hostname=server_hostname)
           ^^^^^^^^^^^^^^^^^^^^^^^^^^^^^^^^^^^^^^^^^^^^^^^^^^^^^^^^^^^^^^
  File "C:\ProgramData\miniconda3\envs\wandbtestp11\Lib\ssl.py", line 517, in wrap_socket
    return self.sslsocket_class._create(
           ^^^^^^^^^^^^^^^^^^^^^^^^^^^^^
  File "C:\ProgramData\miniconda3\envs\wandbtestp11\Lib\ssl.py", line 1104, in _create
    self.do_handshake()
  File "C:\ProgramData\miniconda3\envs\wandbtestp11\Lib\ssl.py", line 1382, in do_handshake
    self._sslobj.do_handshake()
ssl.SSLCertVerificationError: [SSL: CERTIFICATE_VERIFY_FAILED] certificate verify failed: self-signed certificate in certificate chain (_ssl.c:1006)

During handling of the above exception, another exception occurred:

Traceback (most recent call last):
  File "C:\ProgramData\miniconda3\envs\wandbtestp11\Lib\site-packages\urllib3\connectionpool.py", line 789, in urlopen
    response = self._make_request(
               ^^^^^^^^^^^^^^^^^^^
  File "C:\ProgramData\miniconda3\envs\wandbtestp11\Lib\site-packages\urllib3\connectionpool.py", line 490, in _make_request
    raise new_e
urllib3.exceptions.SSLError: [SSL: CERTIFICATE_VERIFY_FAILED] certificate verify failed: self-signed certificate in certificate chain (_ssl.c:1006)

The above exception was the direct cause of the following exception:

Traceback (most recent call last):
  File "C:\ProgramData\miniconda3\envs\wandbtestp11\Lib\site-packages\requests\adapters.py", line 667, in send
    resp = conn.urlopen(
           ^^^^^^^^^^^^^
  File "C:\ProgramData\miniconda3\envs\wandbtestp11\Lib\site-packages\urllib3\connectionpool.py", line 843, in urlopen
    retries = retries.increment(
              ^^^^^^^^^^^^^^^^^^
  File "C:\ProgramData\miniconda3\envs\wandbtestp11\Lib\site-packages\urllib3\util\retry.py", line 519, in increment
    raise MaxRetryError(_pool, url, reason) from reason  # type: ignore[arg-type]
    ^^^^^^^^^^^^^^^^^^^^^^^^^^^^^^^^^^^^^^^^^^^^^^^^^^^
urllib3.exceptions.MaxRetryError: HTTPSConnectionPool(host='api.wandb.ai', port=443): Max retries exceeded with url: /graphql (Caused by SSLError(SSLCertVerificationError(1, '[SSL: CERTIFICATE_VERIFY_FAILED] certificate verify failed: self-signed certificate in certificate chain (_ssl.c:1006)')))

During handling of the above exception, another exception occurred:

Traceback (most recent call last):
  File "C:\ProgramData\miniconda3\envs\wandbtestp11\Lib\site-packages\wandb\sdk\lib\retry.py", line 131, in __call__
    result = self._call_fn(*args, **kwargs)
             ^^^^^^^^^^^^^^^^^^^^^^^^^^^^^^
  File "C:\ProgramData\miniconda3\envs\wandbtestp11\Lib\site-packages\wandb\sdk\internal\internal_api.py", line 345, in execute
    return self.client.execute(*args, **kwargs)  # type: ignore
           ^^^^^^^^^^^^^^^^^^^^^^^^^^^^^^^^^^^^
  File "C:\ProgramData\miniconda3\envs\wandbtestp11\Lib\site-packages\wandb\vendor\gql-0.2.0\wandb_gql\client.py", line 52, in execute
    result = self._get_result(document, *args, **kwargs)
             ^^^^^^^^^^^^^^^^^^^^^^^^^^^^^^^^^^^^^^^^^^^
  File "C:\ProgramData\miniconda3\envs\wandbtestp11\Lib\site-packages\wandb\vendor\gql-0.2.0\wandb_gql\client.py", line 60, in _get_result
    return self.transport.execute(document, *args, **kwargs)
           ^^^^^^^^^^^^^^^^^^^^^^^^^^^^^^^^^^^^^^^^^^^^^^^^^
  File "C:\ProgramData\miniconda3\envs\wandbtestp11\Lib\site-packages\wandb\sdk\lib\gql_request.py", line 58, in execute
    request = self.session.post(self.url, **post_args)
              ^^^^^^^^^^^^^^^^^^^^^^^^^^^^^^^^^^^^^^^^
  File "C:\ProgramData\miniconda3\envs\wandbtestp11\Lib\site-packages\requests\sessions.py", line 637, in post
    return self.request("POST", url, data=data, json=json, **kwargs)
           ^^^^^^^^^^^^^^^^^^^^^^^^^^^^^^^^^^^^^^^^^^^^^^^^^^^^^^^^^
  File "C:\ProgramData\miniconda3\envs\wandbtestp11\Lib\site-packages\requests\sessions.py", line 589, in request
    resp = self.send(prep, **send_kwargs)
           ^^^^^^^^^^^^^^^^^^^^^^^^^^^^^^
  File "C:\ProgramData\miniconda3\envs\wandbtestp11\Lib\site-packages\requests\sessions.py", line 703, in send
    r = adapter.send(request, **kwargs)
        ^^^^^^^^^^^^^^^^^^^^^^^^^^^^^^^
  File "C:\ProgramData\miniconda3\envs\wandbtestp11\Lib\site-packages\requests\adapters.py", line 698, in send
    raise SSLError(e, request=request)
requests.exceptions.SSLError: HTTPSConnectionPool(host='api.wandb.ai', port=443): Max retries exceeded with url: /graphql (Caused by SSLError(SSLCertVerificationError(1, '[SSL: CERTIFICATE_VERIFY_FAILED] certificate verify failed: self-signed certificate in certificate chain (_ssl.c:1006)')))
2024-07-08 13:22:54,550 DEBUG   HandlerThread:28940 [handler.py:handle_request():158] handle_request: keepalive
2024-07-08 13:22:59,574 DEBUG   HandlerThread:28940 [handler.py:handle_request():158] handle_request: keepalive
2024-07-08 13:23:04,605 DEBUG   HandlerThread:28940 [handler.py:handle_request():158] handle_request: keepalive
2024-07-08 13:23:09,636 DEBUG   HandlerThread:28940 [handler.py:handle_request():158] handle_request: keepalive
2024-07-08 13:23:14,665 DEBUG   HandlerThread:28940 [handler.py:handle_request():158] handle_request: keepalive
2024-07-08 13:23:19,711 DEBUG   HandlerThread:28940 [handler.py:handle_request():158] handle_request: keepalive
2024-07-08 13:23:24,740 DEBUG   HandlerThread:28940 [handler.py:handle_request():158] handle_request: keepalive
2024-07-08 13:23:29,773 DEBUG   HandlerThread:28940 [handler.py:handle_request():158] handle_request: keepalive
2024-07-08 13:23:34,802 DEBUG   HandlerThread:28940 [handler.py:handle_request():158] handle_request: keepalive
2024-07-08 13:23:39,829 DEBUG   HandlerThread:28940 [handler.py:handle_request():158] handle_request: keepalive
2024-07-08 13:23:44,856 DEBUG   HandlerThread:28940 [handler.py:handle_request():158] handle_request: keepalive
2024-07-08 13:23:49,904 DEBUG   HandlerThread:28940 [handler.py:handle_request():158] handle_request: keepalive
2024-07-08 13:23:54,929 DEBUG   HandlerThread:28940 [handler.py:handle_request():158] handle_request: keepalive
2024-07-08 13:23:59,976 DEBUG   HandlerThread:28940 [handler.py:handle_request():158] handle_request: keepalive
2024-07-08 13:24:05,002 DEBUG   HandlerThread:28940 [handler.py:handle_request():158] handle_request: keepalive
2024-07-08 13:24:10,043 DEBUG   HandlerThread:28940 [handler.py:handle_request():158] handle_request: keepalive
2024-07-08 13:24:15,064 DEBUG   HandlerThread:28940 [handler.py:handle_request():158] handle_request: keepalive
2024-07-08 13:24:20,109 DEBUG   HandlerThread:28940 [handler.py:handle_request():158] handle_request: cancel
2024-07-08 13:24:20,109 DEBUG   HandlerThread:28940 [handler.py:handle_request():158] handle_request: cancel
2024-07-08 13:24:20,109 DEBUG   SenderThread:28940 [sender.py:send():388] Record cancelled: run
2024-07-08 13:24:20,109 DEBUG   HandlerThread:28940 [handler.py:handle_request():158] handle_request: status_report
2024-07-08 13:24:20,719 DEBUG   HandlerThread:28940 [handler.py:handle_request():158] handle_request: shutdown
2024-07-08 13:24:20,719 INFO    HandlerThread:28940 [handler.py:finish():882] shutting down handler
2024-07-08 13:24:21,114 INFO    WriterThread:28940 [datastore.py:close():296] close: D:\Works\SomeCodes\testing-wandb\wandb\run-20240708_132249-glh15ugv\run-glh15ugv.wandb
2024-07-08 13:24:21,114 INFO    SenderThread:28940 [sender.py:finish():1608] shutting down sender
