2024-07-08 12:23:18,065 INFO    MainThread:38104 [wandb_setup.py:_flush():76] Current SDK version is 0.17.4
2024-07-08 12:23:18,065 INFO    MainThread:38104 [wandb_setup.py:_flush():76] Configure stats pid to 38104
2024-07-08 12:23:18,065 INFO    MainThread:38104 [wandb_setup.py:_flush():76] Loading settings from C:\Users\4475358\.config\wandb\settings
2024-07-08 12:23:18,065 INFO    MainThread:38104 [wandb_setup.py:_flush():76] Loading settings from D:\Works\SomeCodes\testing-wandb\wandb\settings
2024-07-08 12:23:18,065 INFO    MainThread:38104 [wandb_setup.py:_flush():76] Loading settings from environment variables: {}
2024-07-08 12:23:18,065 INFO    MainThread:38104 [wandb_setup.py:_flush():76] Applying setup settings: {'_disable_service': False}
2024-07-08 12:23:18,066 INFO    MainThread:38104 [wandb_setup.py:_flush():76] Inferring run settings from compute environment: {'program_relpath': 'test-wandb.py', 'program_abspath': 'd:\\Works\\SomeCodes\\testing-wandb\\test-wandb.py', 'program': 'd:\\Works\\SomeCodes\\testing-wandb\\test-wandb.py'}
2024-07-08 12:23:18,066 INFO    MainThread:38104 [wandb_setup.py:_flush():76] Applying login settings: {}
2024-07-08 12:23:18,066 INFO    MainThread:38104 [wandb_init.py:_log_setup():529] Logging user logs to D:\Works\SomeCodes\testing-wandb\wandb\run-20240708_122318-fdlfg6d8\logs\debug.log
2024-07-08 12:23:18,066 INFO    MainThread:38104 [wandb_init.py:_log_setup():530] Logging internal logs to D:\Works\SomeCodes\testing-wandb\wandb\run-20240708_122318-fdlfg6d8\logs\debug-internal.log
2024-07-08 12:23:18,067 INFO    MainThread:38104 [wandb_init.py:init():569] calling init triggers
2024-07-08 12:23:18,067 INFO    MainThread:38104 [wandb_init.py:init():576] wandb.init called with sweep_config: {}
config: {}
2024-07-08 12:23:18,067 INFO    MainThread:38104 [wandb_init.py:init():619] starting backend
2024-07-08 12:23:18,067 INFO    MainThread:38104 [wandb_init.py:init():623] setting up manager
2024-07-08 12:23:18,068 INFO    MainThread:38104 [backend.py:_multiprocessing_setup():105] multiprocessing start_methods=spawn, using: spawn
2024-07-08 12:23:18,070 INFO    MainThread:38104 [wandb_init.py:init():631] backend started and connected
2024-07-08 12:23:18,071 INFO    MainThread:38104 [wandb_init.py:init():720] updated telemetry
2024-07-08 12:23:18,073 INFO    MainThread:38104 [wandb_init.py:init():753] communicating run to backend with 90.0 second timeout
2024-07-08 12:23:18,138 INFO    Thread-5 (wrapped_target):38104 [retry.py:__call__():172] Retry attempt failed:
Traceback (most recent call last):
  File "C:\Users\4475358\.conda\envs\testing-123\lib\site-packages\urllib3\connectionpool.py", line 467, in _make_request
    self._validate_conn(conn)
  File "C:\Users\4475358\.conda\envs\testing-123\lib\site-packages\urllib3\connectionpool.py", line 1099, in _validate_conn
    conn.connect()
  File "C:\Users\4475358\.conda\envs\testing-123\lib\site-packages\urllib3\connection.py", line 653, in connect
    sock_and_verified = _ssl_wrap_socket_and_match_hostname(
  File "C:\Users\4475358\.conda\envs\testing-123\lib\site-packages\urllib3\connection.py", line 806, in _ssl_wrap_socket_and_match_hostname
    ssl_sock = ssl_wrap_socket(
  File "C:\Users\4475358\.conda\envs\testing-123\lib\site-packages\urllib3\util\ssl_.py", line 465, in ssl_wrap_socket
    ssl_sock = _ssl_wrap_socket_impl(sock, context, tls_in_tls, server_hostname)
  File "C:\Users\4475358\.conda\envs\testing-123\lib\site-packages\urllib3\util\ssl_.py", line 509, in _ssl_wrap_socket_impl
    return ssl_context.wrap_socket(sock, server_hostname=server_hostname)
  File "C:\Users\4475358\.conda\envs\testing-123\lib\ssl.py", line 513, in wrap_socket
    return self.sslsocket_class._create(
  File "C:\Users\4475358\.conda\envs\testing-123\lib\ssl.py", line 1104, in _create
    self.do_handshake()
  File "C:\Users\4475358\.conda\envs\testing-123\lib\ssl.py", line 1375, in do_handshake
    self._sslobj.do_handshake()
ssl.SSLCertVerificationError: [SSL: CERTIFICATE_VERIFY_FAILED] certificate verify failed: self-signed certificate in certificate chain (_ssl.c:1007)

During handling of the above exception, another exception occurred:

Traceback (most recent call last):
  File "C:\Users\4475358\.conda\envs\testing-123\lib\site-packages\urllib3\connectionpool.py", line 793, in urlopen
    response = self._make_request(
  File "C:\Users\4475358\.conda\envs\testing-123\lib\site-packages\urllib3\connectionpool.py", line 491, in _make_request
    raise new_e
urllib3.exceptions.SSLError: [SSL: CERTIFICATE_VERIFY_FAILED] certificate verify failed: self-signed certificate in certificate chain (_ssl.c:1007)

The above exception was the direct cause of the following exception:

Traceback (most recent call last):
  File "C:\Users\4475358\.conda\envs\testing-123\lib\site-packages\requests\adapters.py", line 486, in send
    resp = conn.urlopen(
  File "C:\Users\4475358\.conda\envs\testing-123\lib\site-packages\urllib3\connectionpool.py", line 847, in urlopen
    retries = retries.increment(
  File "C:\Users\4475358\.conda\envs\testing-123\lib\site-packages\urllib3\util\retry.py", line 515, in increment
    raise MaxRetryError(_pool, url, reason) from reason  # type: ignore[arg-type]
urllib3.exceptions.MaxRetryError: HTTPSConnectionPool(host='api.wandb.ai', port=443): Max retries exceeded with url: /graphql (Caused by SSLError(SSLCertVerificationError(1, '[SSL: CERTIFICATE_VERIFY_FAILED] certificate verify failed: self-signed certificate in certificate chain (_ssl.c:1007)')))

During handling of the above exception, another exception occurred:

Traceback (most recent call last):
  File "C:\Users\4475358\.conda\envs\testing-123\lib\site-packages\wandb\sdk\lib\retry.py", line 131, in __call__
    result = self._call_fn(*args, **kwargs)
  File "C:\Users\4475358\.conda\envs\testing-123\lib\site-packages\wandb\sdk\internal\internal_api.py", line 345, in execute
    return self.client.execute(*args, **kwargs)  # type: ignore
  File "C:\Users\4475358\.conda\envs\testing-123\lib\site-packages\wandb\vendor\gql-0.2.0\wandb_gql\client.py", line 52, in execute
    result = self._get_result(document, *args, **kwargs)
  File "C:\Users\4475358\.conda\envs\testing-123\lib\site-packages\wandb\vendor\gql-0.2.0\wandb_gql\client.py", line 60, in _get_result
    return self.transport.execute(document, *args, **kwargs)
  File "C:\Users\4475358\.conda\envs\testing-123\lib\site-packages\wandb\sdk\lib\gql_request.py", line 58, in execute
    request = self.session.post(self.url, **post_args)
  File "C:\Users\4475358\.conda\envs\testing-123\lib\site-packages\requests\sessions.py", line 637, in post
    return self.request("POST", url, data=data, json=json, **kwargs)
  File "C:\Users\4475358\.conda\envs\testing-123\lib\site-packages\requests\sessions.py", line 589, in request
    resp = self.send(prep, **send_kwargs)
  File "C:\Users\4475358\.conda\envs\testing-123\lib\site-packages\requests\sessions.py", line 703, in send
    r = adapter.send(request, **kwargs)
  File "C:\Users\4475358\.conda\envs\testing-123\lib\site-packages\requests\adapters.py", line 517, in send
    raise SSLError(e, request=request)
requests.exceptions.SSLError: HTTPSConnectionPool(host='api.wandb.ai', port=443): Max retries exceeded with url: /graphql (Caused by SSLError(SSLCertVerificationError(1, '[SSL: CERTIFICATE_VERIFY_FAILED] certificate verify failed: self-signed certificate in certificate chain (_ssl.c:1007)')))
2024-07-08 12:24:26,162 WARNING MsgRouterThr:38104 [router.py:message_loop():77] message_loop has been closed
